<?xml version="1.0"?>
<robot name="abot"> 
<!--********************************xxxxxxxxx********************************-->
<!--********************************base_link********************************-->
	<link name="base_link">
		<visual>
		<origin xyz="0 0 0" rpy="0 0 0"/>
		<geometry>
			<box size="0.30 0.25 0.15"/>
		</geometry>
			<material name="yellow">
				<color rgba="1 0.4 0 0.5"/>
			</material>
		</visual>
	</link>
<!--********************************left_front_link********************************-->
	<link name="left_front_link">
		<visual>
			<origin xyz="0 0 0" rpy="1.5707 0 0"/>
			<geometry>
				<cylinder radius="0.06" length="0.025"/>
			</geometry>
			<material name="white">
				<color rgba="1 1 1 0.9"/>
			</material>
		</visual>
	</link>
	<joint name="left_front_joint" type="continuous">
		<origin xyz="0.10 0.15 -0.05" rpy="0 0 0"/>
		<parent link="base_link"/>
		<child link="left_front_link"/>
		<axis xyz="0 1 0"/>
	</joint>
<!--********************************left_back_link********************************-->
	<link name="left_back_link">
		<visual>
			<origin xyz="0 0 0" rpy="1.5707 0 0"/>
			<geometry>
				<cylinder radius="0.06" length="0.025"/>
			</geometry>
			<material name="white">
				<color rgba="1 1 1 0.9"/>
			</material>
		</visual>
	</link>
	<joint name="left_back_link" type="continuous">
		<origin xyz="-0.10 0.15 -0.05" rpy="0 0 0"/>
		<parent link="base_link"/>
		<child link="left_back_link"/>
		<axis xyz="0 1 0"/>
	</joint>
<!--********************************right_front_link********************************-->
	<link name="right_front_link">
		<visual>
			<origin xyz="0 0 0" rpy="1.5707 0 0"/>
			<geometry>
				<cylinder radius="0.06" length="0.025"/>
			</geometry>
			<material name="white">
				<color rgba="1 1 1 0.9"/>
			</material>
		</visual>
	</link>
	<joint name="right_front_link" type="continuous">
		<origin xyz="0.10 -0.15 -0.05" rpy="0 0 0"/>
		<parent link="base_link"/>
		<child link="right_front_link"/>
		<axis xyz="0 1 0"/>
	</joint>
<!--********************************right_back_link********************************-->
	<link name="right_back_link">
		<visual>
			<origin xyz="0 0 0" rpy="1.5707 0 0"/>
			<geometry>
				<cylinder radius="0.06" length="0.025"/>
			</geometry>
			<material name="white">
				<color rgba="1 1 1 0.9"/>
			</material>
		</visual>
	</link>
	<joint name="right_back_link" type="continuous">
		<origin xyz="-0.10 -0.15 -0.05" rpy="0 0 0"/>
		<parent link="base_link"/>
		<child link="right_back_link"/>
		<axis xyz="0 1 0"/>
	</joint>
<!--********************************laser_link********************************-->
	<link name="laser_link">
		<visual>
			<origin xyz="0 0 0" rpy="0 0 0"/>
			<geometry>
				<cylinder radius="0.04" length="0.040"/>
			</geometry>
			<material name="black">
				<color rgba="0 0 0 0.95"/>
			</material>
		</visual>
	</link>
<!--********************************laser_joint********************************-->
	<joint name="laser_joint" type="fixed">
		<origin xyz="0 0 0.09" rpy="0 0 0"/>
		<parent link="base_link"/>
		<child link="laser_link"/>
	</joint>

</robot>
